[2022-11-08T17:49:06.026+0000] {taskinstance.py:1165} INFO - Dependencies all met for <TaskInstance: 6-monitoring_1.task5 scheduled__2022-01-15T00:00:00+00:00 [queued]>
[2022-11-08T17:49:06.064+0000] {taskinstance.py:1165} INFO - Dependencies all met for <TaskInstance: 6-monitoring_1.task5 scheduled__2022-01-15T00:00:00+00:00 [queued]>
[2022-11-08T17:49:06.065+0000] {taskinstance.py:1362} INFO - 
--------------------------------------------------------------------------------
[2022-11-08T17:49:06.067+0000] {taskinstance.py:1363} INFO - Starting attempt 1 of 1
[2022-11-08T17:49:06.068+0000] {taskinstance.py:1364} INFO - 
--------------------------------------------------------------------------------
[2022-11-08T17:49:06.102+0000] {taskinstance.py:1383} INFO - Executing <Task(BashOperator): task5> on 2022-01-15 00:00:00+00:00
[2022-11-08T17:49:06.114+0000] {standard_task_runner.py:55} INFO - Started process 714 to run task
[2022-11-08T17:49:06.125+0000] {standard_task_runner.py:82} INFO - Running: ['***', 'tasks', 'run', '6-monitoring_1', 'task5', 'scheduled__2022-01-15T00:00:00+00:00', '--job-id', '420', '--raw', '--subdir', 'DAGS_FOLDER/6.1-monitoring.py', '--cfg-path', '/tmp/tmphhdtyi64']
[2022-11-08T17:49:06.127+0000] {standard_task_runner.py:83} INFO - Job 420: Subtask task5
[2022-11-08T17:49:06.280+0000] {task_command.py:376} INFO - Running <TaskInstance: 6-monitoring_1.task5 scheduled__2022-01-15T00:00:00+00:00 [running]> on host 638485efabe7
[2022-11-08T17:49:06.435+0000] {taskinstance.py:1592} INFO - Exporting the following env vars:
AIRFLOW_CTX_DAG_OWNER=***
AIRFLOW_CTX_DAG_ID=6-monitoring_1
AIRFLOW_CTX_TASK_ID=task5
AIRFLOW_CTX_EXECUTION_DATE=2022-01-15T00:00:00+00:00
AIRFLOW_CTX_TRY_NUMBER=1
AIRFLOW_CTX_DAG_RUN_ID=scheduled__2022-01-15T00:00:00+00:00
[2022-11-08T17:49:06.463+0000] {subprocess.py:63} INFO - Tmp dir root location: 
 /tmp
[2022-11-08T17:49:06.465+0000] {subprocess.py:75} INFO - Running command: ['/bin/bash', '-c', "sleep 2 && echo 'task5'"]
[2022-11-08T17:49:06.485+0000] {subprocess.py:86} INFO - Output:
[2022-11-08T17:49:08.607+0000] {subprocess.py:93} INFO - task5
[2022-11-08T17:49:08.609+0000] {subprocess.py:97} INFO - Command exited with return code 0
[2022-11-08T17:49:08.641+0000] {taskinstance.py:1406} INFO - Marking task as SUCCESS. dag_id=6-monitoring_1, task_id=task5, execution_date=20220115T000000, start_date=20221108T174906, end_date=20221108T174908
[2022-11-08T17:49:08.714+0000] {local_task_job.py:164} INFO - Task exited with return code 0
[2022-11-08T17:49:08.736+0000] {local_task_job.py:273} INFO - 0 downstream tasks scheduled from follow-on schedule check
[2022-11-08T20:29:59.148+0000] {taskinstance.py:1165} INFO - Dependencies all met for <TaskInstance: 6-monitoring_1.task5 scheduled__2022-01-15T00:00:00+00:00 [queued]>
[2022-11-08T20:29:59.200+0000] {taskinstance.py:1165} INFO - Dependencies all met for <TaskInstance: 6-monitoring_1.task5 scheduled__2022-01-15T00:00:00+00:00 [queued]>
[2022-11-08T20:29:59.201+0000] {taskinstance.py:1362} INFO - 
--------------------------------------------------------------------------------
[2022-11-08T20:29:59.202+0000] {taskinstance.py:1363} INFO - Starting attempt 1 of 1
[2022-11-08T20:29:59.204+0000] {taskinstance.py:1364} INFO - 
--------------------------------------------------------------------------------
[2022-11-08T20:29:59.268+0000] {taskinstance.py:1383} INFO - Executing <Task(BashOperator): task5> on 2022-01-15 00:00:00+00:00
[2022-11-08T20:29:59.292+0000] {standard_task_runner.py:55} INFO - Started process 3770 to run task
[2022-11-08T20:29:59.306+0000] {standard_task_runner.py:82} INFO - Running: ['***', 'tasks', 'run', '6-monitoring_1', 'task5', 'scheduled__2022-01-15T00:00:00+00:00', '--job-id', '560', '--raw', '--subdir', 'DAGS_FOLDER/6.1-monitoring.py', '--cfg-path', '/tmp/tmpku1watge']
[2022-11-08T20:29:59.308+0000] {standard_task_runner.py:83} INFO - Job 560: Subtask task5
[2022-11-08T20:31:07.126+0000] {standard_task_runner.py:105} ERROR - Failed to execute job 560 for task task5 ((psycopg2.OperationalError) could not translate host name "postgres" to address: Temporary failure in name resolution

(Background on this error at: https://sqlalche.me/e/14/e3q8); 3770)
[2022-11-08T20:31:12.524+0000] {base_job.py:232} ERROR - LocalTaskJob heartbeat got an exception
Traceback (most recent call last):
  File "/home/airflow/.local/lib/python3.7/site-packages/sqlalchemy/engine/base.py", line 3243, in _wrap_pool_connect
    return fn()
  File "/home/airflow/.local/lib/python3.7/site-packages/sqlalchemy/pool/base.py", line 310, in connect
    return _ConnectionFairy._checkout(self)
  File "/home/airflow/.local/lib/python3.7/site-packages/sqlalchemy/pool/base.py", line 868, in _checkout
    fairy = _ConnectionRecord.checkout(pool)
  File "/home/airflow/.local/lib/python3.7/site-packages/sqlalchemy/pool/base.py", line 476, in checkout
    rec = pool._do_get()
  File "/home/airflow/.local/lib/python3.7/site-packages/sqlalchemy/pool/impl.py", line 256, in _do_get
    return self._create_connection()
  File "/home/airflow/.local/lib/python3.7/site-packages/sqlalchemy/pool/base.py", line 256, in _create_connection
    return _ConnectionRecord(self)
  File "/home/airflow/.local/lib/python3.7/site-packages/sqlalchemy/pool/base.py", line 371, in __init__
    self.__connect()
  File "/home/airflow/.local/lib/python3.7/site-packages/sqlalchemy/pool/base.py", line 666, in __connect
    pool.logger.debug("Error on connect(): %s", e)
  File "/home/airflow/.local/lib/python3.7/site-packages/sqlalchemy/util/langhelpers.py", line 72, in __exit__
    with_traceback=exc_tb,
  File "/home/airflow/.local/lib/python3.7/site-packages/sqlalchemy/util/compat.py", line 207, in raise_
    raise exception
  File "/home/airflow/.local/lib/python3.7/site-packages/sqlalchemy/pool/base.py", line 661, in __connect
    self.dbapi_connection = connection = pool._invoke_creator(self)
  File "/home/airflow/.local/lib/python3.7/site-packages/sqlalchemy/engine/create.py", line 590, in connect
    return dialect.connect(*cargs, **cparams)
  File "/home/airflow/.local/lib/python3.7/site-packages/sqlalchemy/engine/default.py", line 584, in connect
    return self.dbapi.connect(*cargs, **cparams)
  File "/home/airflow/.local/lib/python3.7/site-packages/psycopg2/__init__.py", line 122, in connect
    conn = _connect(dsn, connection_factory=connection_factory, **kwasync)
psycopg2.OperationalError: could not translate host name "postgres" to address: Temporary failure in name resolution


The above exception was the direct cause of the following exception:

Traceback (most recent call last):
  File "/home/airflow/.local/lib/python3.7/site-packages/airflow/jobs/base_job.py", line 204, in heartbeat
    session.merge(self)
  File "/home/airflow/.local/lib/python3.7/site-packages/sqlalchemy/orm/session.py", line 2961, in merge
    _resolve_conflict_map=_resolve_conflict_map,
  File "/home/airflow/.local/lib/python3.7/site-packages/sqlalchemy/orm/session.py", line 3039, in _merge
    options=options,
  File "/home/airflow/.local/lib/python3.7/site-packages/sqlalchemy/orm/session.py", line 2775, in get
    identity_token=identity_token,
  File "/home/airflow/.local/lib/python3.7/site-packages/sqlalchemy/orm/session.py", line 2878, in _get_impl
    load_options=load_options,
  File "/home/airflow/.local/lib/python3.7/site-packages/sqlalchemy/orm/loading.py", line 534, in load_on_pk_identity
    bind_arguments=bind_arguments,
  File "/home/airflow/.local/lib/python3.7/site-packages/sqlalchemy/orm/session.py", line 1688, in execute
    conn = self._connection_for_bind(bind)
  File "/home/airflow/.local/lib/python3.7/site-packages/sqlalchemy/orm/session.py", line 1530, in _connection_for_bind
    engine, execution_options
  File "/home/airflow/.local/lib/python3.7/site-packages/sqlalchemy/orm/session.py", line 747, in _connection_for_bind
    conn = bind.connect()
  File "/home/airflow/.local/lib/python3.7/site-packages/sqlalchemy/engine/base.py", line 3197, in connect
    return self._connection_cls(self, close_with_result=close_with_result)
  File "/home/airflow/.local/lib/python3.7/site-packages/sqlalchemy/engine/base.py", line 96, in __init__
    else engine.raw_connection()
  File "/home/airflow/.local/lib/python3.7/site-packages/sqlalchemy/engine/base.py", line 3276, in raw_connection
    return self._wrap_pool_connect(self.pool.connect, _connection)
  File "/home/airflow/.local/lib/python3.7/site-packages/sqlalchemy/engine/base.py", line 3247, in _wrap_pool_connect
    e, dialect, self
  File "/home/airflow/.local/lib/python3.7/site-packages/sqlalchemy/engine/base.py", line 2101, in _handle_dbapi_exception_noconnection
    sqlalchemy_exception, with_traceback=exc_info[2], from_=e
  File "/home/airflow/.local/lib/python3.7/site-packages/sqlalchemy/util/compat.py", line 207, in raise_
    raise exception
  File "/home/airflow/.local/lib/python3.7/site-packages/sqlalchemy/engine/base.py", line 3243, in _wrap_pool_connect
    return fn()
  File "/home/airflow/.local/lib/python3.7/site-packages/sqlalchemy/pool/base.py", line 310, in connect
    return _ConnectionFairy._checkout(self)
  File "/home/airflow/.local/lib/python3.7/site-packages/sqlalchemy/pool/base.py", line 868, in _checkout
    fairy = _ConnectionRecord.checkout(pool)
  File "/home/airflow/.local/lib/python3.7/site-packages/sqlalchemy/pool/base.py", line 476, in checkout
    rec = pool._do_get()
  File "/home/airflow/.local/lib/python3.7/site-packages/sqlalchemy/pool/impl.py", line 256, in _do_get
    return self._create_connection()
  File "/home/airflow/.local/lib/python3.7/site-packages/sqlalchemy/pool/base.py", line 256, in _create_connection
    return _ConnectionRecord(self)
  File "/home/airflow/.local/lib/python3.7/site-packages/sqlalchemy/pool/base.py", line 371, in __init__
    self.__connect()
  File "/home/airflow/.local/lib/python3.7/site-packages/sqlalchemy/pool/base.py", line 666, in __connect
    pool.logger.debug("Error on connect(): %s", e)
  File "/home/airflow/.local/lib/python3.7/site-packages/sqlalchemy/util/langhelpers.py", line 72, in __exit__
    with_traceback=exc_tb,
  File "/home/airflow/.local/lib/python3.7/site-packages/sqlalchemy/util/compat.py", line 207, in raise_
    raise exception
  File "/home/airflow/.local/lib/python3.7/site-packages/sqlalchemy/pool/base.py", line 661, in __connect
    self.dbapi_connection = connection = pool._invoke_creator(self)
  File "/home/airflow/.local/lib/python3.7/site-packages/sqlalchemy/engine/create.py", line 590, in connect
    return dialect.connect(*cargs, **cparams)
  File "/home/airflow/.local/lib/python3.7/site-packages/sqlalchemy/engine/default.py", line 584, in connect
    return self.dbapi.connect(*cargs, **cparams)
  File "/home/airflow/.local/lib/python3.7/site-packages/psycopg2/__init__.py", line 122, in connect
    conn = _connect(dsn, connection_factory=connection_factory, **kwasync)
sqlalchemy.exc.OperationalError: (psycopg2.OperationalError) could not translate host name "postgres" to address: Temporary failure in name resolution

(Background on this error at: https://sqlalche.me/e/14/e3q8)
[2022-11-08T20:32:30.777+0000] {local_task_job.py:164} INFO - Task exited with return code 1
[2022-11-08T20:43:01.279+0000] {local_task_job.py:273} INFO - 0 downstream tasks scheduled from follow-on schedule check
