[2022-11-09T14:58:54.792+0000] {taskinstance.py:1165} INFO - Dependencies all met for <TaskInstance: 6-monitoring_2.task4 scheduled__2022-01-02T00:00:00+00:00 [queued]>
[2022-11-09T14:58:54.825+0000] {taskinstance.py:1165} INFO - Dependencies all met for <TaskInstance: 6-monitoring_2.task4 scheduled__2022-01-02T00:00:00+00:00 [queued]>
[2022-11-09T14:58:54.826+0000] {taskinstance.py:1362} INFO - 
--------------------------------------------------------------------------------
[2022-11-09T14:58:54.828+0000] {taskinstance.py:1363} INFO - Starting attempt 2 of 3
[2022-11-09T14:58:54.829+0000] {taskinstance.py:1364} INFO - 
--------------------------------------------------------------------------------
[2022-11-09T14:58:54.859+0000] {taskinstance.py:1383} INFO - Executing <Task(PythonOperator): task4> on 2022-01-02 00:00:00+00:00
[2022-11-09T14:58:54.869+0000] {standard_task_runner.py:55} INFO - Started process 579 to run task
[2022-11-09T14:58:54.873+0000] {standard_task_runner.py:82} INFO - Running: ['***', 'tasks', 'run', '6-monitoring_2', 'task4', 'scheduled__2022-01-02T00:00:00+00:00', '--job-id', '605', '--raw', '--subdir', 'DAGS_FOLDER/6.2-monitoring.py', '--cfg-path', '/tmp/tmph272o83c']
[2022-11-09T14:58:54.874+0000] {standard_task_runner.py:83} INFO - Job 605: Subtask task4
[2022-11-09T14:58:54.990+0000] {task_command.py:376} INFO - Running <TaskInstance: 6-monitoring_2.task4 scheduled__2022-01-02T00:00:00+00:00 [running]> on host 638485efabe7
[2022-11-09T14:58:55.123+0000] {taskinstance.py:1592} INFO - Exporting the following env vars:
AIRFLOW_CTX_DAG_OWNER=***
AIRFLOW_CTX_DAG_ID=6-monitoring_2
AIRFLOW_CTX_TASK_ID=task4
AIRFLOW_CTX_EXECUTION_DATE=2022-01-02T00:00:00+00:00
AIRFLOW_CTX_TRY_NUMBER=2
AIRFLOW_CTX_DAG_RUN_ID=scheduled__2022-01-02T00:00:00+00:00
[2022-11-09T14:58:55.124+0000] {taskinstance.py:1851} ERROR - Task failed with exception
Traceback (most recent call last):
  File "/home/airflow/.local/lib/python3.7/site-packages/airflow/operators/python.py", line 175, in execute
    return_value = self.execute_callable()
  File "/home/airflow/.local/lib/python3.7/site-packages/airflow/operators/python.py", line 193, in execute_callable
    return self.python_callable(*self.op_args, **self.op_kwargs)
  File "/opt/airflow/dags/6.2-monitoring.py", line 8, in myfunction
    raise Exception
Exception
[2022-11-09T14:58:55.146+0000] {taskinstance.py:1406} INFO - Marking task as UP_FOR_RETRY. dag_id=6-monitoring_2, task_id=task4, execution_date=20220102T000000, start_date=20221109T145854, end_date=20221109T145855
[2022-11-09T14:58:55.166+0000] {standard_task_runner.py:105} ERROR - Failed to execute job 605 for task task4 (; 579)
[2022-11-09T14:58:55.190+0000] {local_task_job.py:164} INFO - Task exited with return code 1
[2022-11-09T14:58:55.245+0000] {local_task_job.py:273} INFO - 0 downstream tasks scheduled from follow-on schedule check
