[2022-11-17T16:53:35.852+0000] {taskinstance.py:1165} INFO - Dependencies all met for <TaskInstance: MyPersonalAirflowProject.Data_Team_Notification scheduled__2022-11-16T00:00:00+00:00 [queued]>
[2022-11-17T16:53:35.865+0000] {taskinstance.py:1165} INFO - Dependencies all met for <TaskInstance: MyPersonalAirflowProject.Data_Team_Notification scheduled__2022-11-16T00:00:00+00:00 [queued]>
[2022-11-17T16:53:35.866+0000] {taskinstance.py:1362} INFO - 
--------------------------------------------------------------------------------
[2022-11-17T16:53:35.881+0000] {taskinstance.py:1363} INFO - Starting attempt 5 of 5
[2022-11-17T16:53:35.882+0000] {taskinstance.py:1364} INFO - 
--------------------------------------------------------------------------------
[2022-11-17T16:53:35.920+0000] {taskinstance.py:1383} INFO - Executing <Task(NotifyOperator): Data_Team_Notification> on 2022-11-16 00:00:00+00:00
[2022-11-17T16:53:35.927+0000] {standard_task_runner.py:55} INFO - Started process 5407 to run task
[2022-11-17T16:53:35.930+0000] {standard_task_runner.py:82} INFO - Running: ['***', 'tasks', 'run', 'MyPersonalAirflowProject', 'Data_Team_Notification', 'scheduled__2022-11-16T00:00:00+00:00', '--job-id', '2411', '--raw', '--subdir', 'DAGS_FOLDER/FinalPersonalProject.py', '--cfg-path', '/tmp/tmpt0d_0of8']
[2022-11-17T16:53:35.931+0000] {standard_task_runner.py:83} INFO - Job 2411: Subtask Data_Team_Notification
[2022-11-17T16:53:36.091+0000] {task_command.py:376} INFO - Running <TaskInstance: MyPersonalAirflowProject.Data_Team_Notification scheduled__2022-11-16T00:00:00+00:00 [running]> on host 638485efabe7
[2022-11-17T16:53:36.173+0000] {taskinstance.py:1592} INFO - Exporting the following env vars:
AIRFLOW_CTX_DAG_OWNER=***
AIRFLOW_CTX_DAG_ID=MyPersonalAirflowProject
AIRFLOW_CTX_TASK_ID=Data_Team_Notification
AIRFLOW_CTX_EXECUTION_DATE=2022-11-16T00:00:00+00:00
AIRFLOW_CTX_TRY_NUMBER=5
AIRFLOW_CTX_DAG_RUN_ID=scheduled__2022-11-16T00:00:00+00:00
[2022-11-17T16:53:36.174+0000] {taskinstance.py:1851} ERROR - Task failed with exception
Traceback (most recent call last):
  File "/opt/airflow/dags/FinalPersonalProject_Notification.py", line 9, in execute
    print(f"Hi Data team, Space X data for {kwargs['logical_date']}  are now available!.. Please check them out!")
NameError: name 'kwargs' is not defined
[2022-11-17T16:53:36.188+0000] {taskinstance.py:1406} INFO - Marking task as FAILED. dag_id=MyPersonalAirflowProject, task_id=Data_Team_Notification, execution_date=20221116T000000, start_date=20221117T165335, end_date=20221117T165336
[2022-11-17T16:53:36.205+0000] {standard_task_runner.py:105} ERROR - Failed to execute job 2411 for task Data_Team_Notification (name 'kwargs' is not defined; 5407)
[2022-11-17T16:53:36.223+0000] {local_task_job.py:164} INFO - Task exited with return code 1
[2022-11-17T16:53:36.247+0000] {local_task_job.py:273} INFO - 0 downstream tasks scheduled from follow-on schedule check
