[2022-11-09T14:56:59.755+0000] {taskinstance.py:1165} INFO - Dependencies all met for <TaskInstance: 6-monitoring_2.task4 scheduled__2022-01-01T00:00:00+00:00 [queued]>
[2022-11-09T14:56:59.776+0000] {taskinstance.py:1165} INFO - Dependencies all met for <TaskInstance: 6-monitoring_2.task4 scheduled__2022-01-01T00:00:00+00:00 [queued]>
[2022-11-09T14:56:59.777+0000] {taskinstance.py:1362} INFO - 
--------------------------------------------------------------------------------
[2022-11-09T14:56:59.778+0000] {taskinstance.py:1363} INFO - Starting attempt 6 of 6
[2022-11-09T14:56:59.779+0000] {taskinstance.py:1364} INFO - 
--------------------------------------------------------------------------------
[2022-11-09T14:56:59.818+0000] {taskinstance.py:1383} INFO - Executing <Task(PythonOperator): task4> on 2022-01-01 00:00:00+00:00
[2022-11-09T14:56:59.830+0000] {standard_task_runner.py:55} INFO - Started process 503 to run task
[2022-11-09T14:56:59.835+0000] {standard_task_runner.py:82} INFO - Running: ['***', 'tasks', 'run', '6-monitoring_2', 'task4', 'scheduled__2022-01-01T00:00:00+00:00', '--job-id', '603', '--raw', '--subdir', 'DAGS_FOLDER/6.2-monitoring.py', '--cfg-path', '/tmp/tmpz0c0yf09']
[2022-11-09T14:56:59.837+0000] {standard_task_runner.py:83} INFO - Job 603: Subtask task4
[2022-11-09T14:56:59.940+0000] {task_command.py:376} INFO - Running <TaskInstance: 6-monitoring_2.task4 scheduled__2022-01-01T00:00:00+00:00 [running]> on host 638485efabe7
[2022-11-09T14:57:00.070+0000] {taskinstance.py:1592} INFO - Exporting the following env vars:
AIRFLOW_CTX_DAG_OWNER=***
AIRFLOW_CTX_DAG_ID=6-monitoring_2
AIRFLOW_CTX_TASK_ID=task4
AIRFLOW_CTX_EXECUTION_DATE=2022-01-01T00:00:00+00:00
AIRFLOW_CTX_TRY_NUMBER=6
AIRFLOW_CTX_DAG_RUN_ID=scheduled__2022-01-01T00:00:00+00:00
[2022-11-09T14:57:00.072+0000] {taskinstance.py:1851} ERROR - Task failed with exception
Traceback (most recent call last):
  File "/home/airflow/.local/lib/python3.7/site-packages/airflow/operators/python.py", line 175, in execute
    return_value = self.execute_callable()
  File "/home/airflow/.local/lib/python3.7/site-packages/airflow/operators/python.py", line 193, in execute_callable
    return self.python_callable(*self.op_args, **self.op_kwargs)
  File "/opt/airflow/dags/6.2-monitoring.py", line 8, in myfunction
    raise Exception
Exception
[2022-11-09T14:57:00.113+0000] {taskinstance.py:1406} INFO - Marking task as FAILED. dag_id=6-monitoring_2, task_id=task4, execution_date=20220101T000000, start_date=20221109T145659, end_date=20221109T145700
[2022-11-09T14:57:00.139+0000] {standard_task_runner.py:105} ERROR - Failed to execute job 603 for task task4 (; 503)
[2022-11-09T14:57:00.255+0000] {local_task_job.py:164} INFO - Task exited with return code 1
[2022-11-09T14:57:00.327+0000] {local_task_job.py:273} INFO - 0 downstream tasks scheduled from follow-on schedule check
