[2022-11-08T20:56:12.947+0000] {taskinstance.py:1165} INFO - Dependencies all met for <TaskInstance: 6-monitoring_2.task4 scheduled__2022-01-01T00:00:00+00:00 [queued]>
[2022-11-08T20:56:12.961+0000] {taskinstance.py:1165} INFO - Dependencies all met for <TaskInstance: 6-monitoring_2.task4 scheduled__2022-01-01T00:00:00+00:00 [queued]>
[2022-11-08T20:56:12.962+0000] {taskinstance.py:1362} INFO - 
--------------------------------------------------------------------------------
[2022-11-08T20:56:12.963+0000] {taskinstance.py:1363} INFO - Starting attempt 3 of 3
[2022-11-08T20:56:12.963+0000] {taskinstance.py:1364} INFO - 
--------------------------------------------------------------------------------
[2022-11-08T20:56:12.981+0000] {taskinstance.py:1383} INFO - Executing <Task(PythonOperator): task4> on 2022-01-01 00:00:00+00:00
[2022-11-08T20:56:12.986+0000] {standard_task_runner.py:55} INFO - Started process 3948 to run task
[2022-11-08T20:56:12.989+0000] {standard_task_runner.py:82} INFO - Running: ['***', 'tasks', 'run', '6-monitoring_2', 'task4', 'scheduled__2022-01-01T00:00:00+00:00', '--job-id', '595', '--raw', '--subdir', 'DAGS_FOLDER/6.2-monitoring.py', '--cfg-path', '/tmp/tmpwyb89921']
[2022-11-08T20:56:12.990+0000] {standard_task_runner.py:83} INFO - Job 595: Subtask task4
[2022-11-08T20:56:13.053+0000] {task_command.py:376} INFO - Running <TaskInstance: 6-monitoring_2.task4 scheduled__2022-01-01T00:00:00+00:00 [running]> on host 638485efabe7
[2022-11-08T20:56:13.125+0000] {taskinstance.py:1592} INFO - Exporting the following env vars:
AIRFLOW_CTX_DAG_OWNER=***
AIRFLOW_CTX_DAG_ID=6-monitoring_2
AIRFLOW_CTX_TASK_ID=task4
AIRFLOW_CTX_EXECUTION_DATE=2022-01-01T00:00:00+00:00
AIRFLOW_CTX_TRY_NUMBER=3
AIRFLOW_CTX_DAG_RUN_ID=scheduled__2022-01-01T00:00:00+00:00
[2022-11-08T20:56:13.126+0000] {taskinstance.py:1851} ERROR - Task failed with exception
Traceback (most recent call last):
  File "/home/airflow/.local/lib/python3.7/site-packages/airflow/operators/python.py", line 175, in execute
    return_value = self.execute_callable()
  File "/home/airflow/.local/lib/python3.7/site-packages/airflow/operators/python.py", line 193, in execute_callable
    return self.python_callable(*self.op_args, **self.op_kwargs)
  File "/opt/airflow/dags/6.2-monitoring.py", line 8, in myfunction
    raise Exception
Exception
[2022-11-08T20:56:13.139+0000] {taskinstance.py:1406} INFO - Marking task as FAILED. dag_id=6-monitoring_2, task_id=task4, execution_date=20220101T000000, start_date=20221108T205612, end_date=20221108T205613
[2022-11-08T20:56:13.157+0000] {standard_task_runner.py:105} ERROR - Failed to execute job 595 for task task4 (; 3948)
[2022-11-08T20:56:13.235+0000] {local_task_job.py:164} INFO - Task exited with return code 1
[2022-11-08T20:56:13.271+0000] {local_task_job.py:273} INFO - 0 downstream tasks scheduled from follow-on schedule check
