[2022-11-04T21:13:39.837+0000] {taskinstance.py:1165} INFO - Dependencies all met for <TaskInstance: orquestation.task2 scheduled__2022-05-25T00:00:00+00:00 [queued]>
[2022-11-04T21:13:39.867+0000] {taskinstance.py:1165} INFO - Dependencies all met for <TaskInstance: orquestation.task2 scheduled__2022-05-25T00:00:00+00:00 [queued]>
[2022-11-04T21:13:39.868+0000] {taskinstance.py:1362} INFO - 
--------------------------------------------------------------------------------
[2022-11-04T21:13:39.869+0000] {taskinstance.py:1363} INFO - Starting attempt 1 of 1
[2022-11-04T21:13:39.871+0000] {taskinstance.py:1364} INFO - 
--------------------------------------------------------------------------------
[2022-11-04T21:13:39.905+0000] {taskinstance.py:1383} INFO - Executing <Task(BashOperator): task2> on 2022-05-25 00:00:00+00:00
[2022-11-04T21:13:39.919+0000] {standard_task_runner.py:55} INFO - Started process 447 to run task
[2022-11-04T21:13:39.925+0000] {standard_task_runner.py:82} INFO - Running: ['***', 'tasks', 'run', 'orquestation', 'task2', 'scheduled__2022-05-25T00:00:00+00:00', '--job-id', '107', '--raw', '--subdir', 'DAGS_FOLDER/5.1-orquestacion.py', '--cfg-path', '/tmp/tmpwn1qz343']
[2022-11-04T21:13:39.926+0000] {standard_task_runner.py:83} INFO - Job 107: Subtask task2
[2022-11-04T21:13:40.081+0000] {task_command.py:376} INFO - Running <TaskInstance: orquestation.task2 scheduled__2022-05-25T00:00:00+00:00 [running]> on host 643e334f405f
[2022-11-04T21:14:07.435+0000] {base_job.py:232} ERROR - LocalTaskJob heartbeat got an exception
Traceback (most recent call last):
  File "/home/airflow/.local/lib/python3.7/site-packages/sqlalchemy/engine/base.py", line 3243, in _wrap_pool_connect
    return fn()
  File "/home/airflow/.local/lib/python3.7/site-packages/sqlalchemy/pool/base.py", line 310, in connect
    return _ConnectionFairy._checkout(self)
  File "/home/airflow/.local/lib/python3.7/site-packages/sqlalchemy/pool/base.py", line 868, in _checkout
    fairy = _ConnectionRecord.checkout(pool)
  File "/home/airflow/.local/lib/python3.7/site-packages/sqlalchemy/pool/base.py", line 476, in checkout
    rec = pool._do_get()
  File "/home/airflow/.local/lib/python3.7/site-packages/sqlalchemy/pool/impl.py", line 256, in _do_get
    return self._create_connection()
  File "/home/airflow/.local/lib/python3.7/site-packages/sqlalchemy/pool/base.py", line 256, in _create_connection
    return _ConnectionRecord(self)
  File "/home/airflow/.local/lib/python3.7/site-packages/sqlalchemy/pool/base.py", line 371, in __init__
    self.__connect()
  File "/home/airflow/.local/lib/python3.7/site-packages/sqlalchemy/pool/base.py", line 666, in __connect
    pool.logger.debug("Error on connect(): %s", e)
  File "/home/airflow/.local/lib/python3.7/site-packages/sqlalchemy/util/langhelpers.py", line 72, in __exit__
    with_traceback=exc_tb,
  File "/home/airflow/.local/lib/python3.7/site-packages/sqlalchemy/util/compat.py", line 207, in raise_
    raise exception
  File "/home/airflow/.local/lib/python3.7/site-packages/sqlalchemy/pool/base.py", line 661, in __connect
    self.dbapi_connection = connection = pool._invoke_creator(self)
  File "/home/airflow/.local/lib/python3.7/site-packages/sqlalchemy/engine/create.py", line 590, in connect
    return dialect.connect(*cargs, **cparams)
  File "/home/airflow/.local/lib/python3.7/site-packages/sqlalchemy/engine/default.py", line 584, in connect
    return self.dbapi.connect(*cargs, **cparams)
  File "/home/airflow/.local/lib/python3.7/site-packages/psycopg2/__init__.py", line 122, in connect
    conn = _connect(dsn, connection_factory=connection_factory, **kwasync)
psycopg2.OperationalError: could not translate host name "postgres" to address: Temporary failure in name resolution


The above exception was the direct cause of the following exception:

Traceback (most recent call last):
  File "/home/airflow/.local/lib/python3.7/site-packages/airflow/jobs/base_job.py", line 204, in heartbeat
    session.merge(self)
  File "/home/airflow/.local/lib/python3.7/site-packages/sqlalchemy/orm/session.py", line 2961, in merge
    _resolve_conflict_map=_resolve_conflict_map,
  File "/home/airflow/.local/lib/python3.7/site-packages/sqlalchemy/orm/session.py", line 3039, in _merge
    options=options,
  File "/home/airflow/.local/lib/python3.7/site-packages/sqlalchemy/orm/session.py", line 2775, in get
    identity_token=identity_token,
  File "/home/airflow/.local/lib/python3.7/site-packages/sqlalchemy/orm/session.py", line 2878, in _get_impl
    load_options=load_options,
  File "/home/airflow/.local/lib/python3.7/site-packages/sqlalchemy/orm/loading.py", line 534, in load_on_pk_identity
    bind_arguments=bind_arguments,
  File "/home/airflow/.local/lib/python3.7/site-packages/sqlalchemy/orm/session.py", line 1688, in execute
    conn = self._connection_for_bind(bind)
  File "/home/airflow/.local/lib/python3.7/site-packages/sqlalchemy/orm/session.py", line 1530, in _connection_for_bind
    engine, execution_options
  File "/home/airflow/.local/lib/python3.7/site-packages/sqlalchemy/orm/session.py", line 747, in _connection_for_bind
    conn = bind.connect()
  File "/home/airflow/.local/lib/python3.7/site-packages/sqlalchemy/engine/base.py", line 3197, in connect
    return self._connection_cls(self, close_with_result=close_with_result)
  File "/home/airflow/.local/lib/python3.7/site-packages/sqlalchemy/engine/base.py", line 96, in __init__
    else engine.raw_connection()
  File "/home/airflow/.local/lib/python3.7/site-packages/sqlalchemy/engine/base.py", line 3276, in raw_connection
    return self._wrap_pool_connect(self.pool.connect, _connection)
  File "/home/airflow/.local/lib/python3.7/site-packages/sqlalchemy/engine/base.py", line 3247, in _wrap_pool_connect
    e, dialect, self
  File "/home/airflow/.local/lib/python3.7/site-packages/sqlalchemy/engine/base.py", line 2101, in _handle_dbapi_exception_noconnection
    sqlalchemy_exception, with_traceback=exc_info[2], from_=e
  File "/home/airflow/.local/lib/python3.7/site-packages/sqlalchemy/util/compat.py", line 207, in raise_
    raise exception
  File "/home/airflow/.local/lib/python3.7/site-packages/sqlalchemy/engine/base.py", line 3243, in _wrap_pool_connect
    return fn()
  File "/home/airflow/.local/lib/python3.7/site-packages/sqlalchemy/pool/base.py", line 310, in connect
    return _ConnectionFairy._checkout(self)
  File "/home/airflow/.local/lib/python3.7/site-packages/sqlalchemy/pool/base.py", line 868, in _checkout
    fairy = _ConnectionRecord.checkout(pool)
  File "/home/airflow/.local/lib/python3.7/site-packages/sqlalchemy/pool/base.py", line 476, in checkout
    rec = pool._do_get()
  File "/home/airflow/.local/lib/python3.7/site-packages/sqlalchemy/pool/impl.py", line 256, in _do_get
    return self._create_connection()
  File "/home/airflow/.local/lib/python3.7/site-packages/sqlalchemy/pool/base.py", line 256, in _create_connection
    return _ConnectionRecord(self)
  File "/home/airflow/.local/lib/python3.7/site-packages/sqlalchemy/pool/base.py", line 371, in __init__
    self.__connect()
  File "/home/airflow/.local/lib/python3.7/site-packages/sqlalchemy/pool/base.py", line 666, in __connect
    pool.logger.debug("Error on connect(): %s", e)
  File "/home/airflow/.local/lib/python3.7/site-packages/sqlalchemy/util/langhelpers.py", line 72, in __exit__
    with_traceback=exc_tb,
  File "/home/airflow/.local/lib/python3.7/site-packages/sqlalchemy/util/compat.py", line 207, in raise_
    raise exception
  File "/home/airflow/.local/lib/python3.7/site-packages/sqlalchemy/pool/base.py", line 661, in __connect
    self.dbapi_connection = connection = pool._invoke_creator(self)
  File "/home/airflow/.local/lib/python3.7/site-packages/sqlalchemy/engine/create.py", line 590, in connect
    return dialect.connect(*cargs, **cparams)
  File "/home/airflow/.local/lib/python3.7/site-packages/sqlalchemy/engine/default.py", line 584, in connect
    return self.dbapi.connect(*cargs, **cparams)
  File "/home/airflow/.local/lib/python3.7/site-packages/psycopg2/__init__.py", line 122, in connect
    conn = _connect(dsn, connection_factory=connection_factory, **kwasync)
sqlalchemy.exc.OperationalError: (psycopg2.OperationalError) could not translate host name "postgres" to address: Temporary failure in name resolution

(Background on this error at: https://sqlalche.me/e/14/e3q8)
[2022-11-04T21:27:38.005+0000] {local_task_job.py:148} ERROR - Heartbeat time limit exceeded!
[2022-11-04T21:27:38.046+0000] {process_utils.py:133} INFO - Sending Signals.SIGTERM to group 447. PIDs of all processes in the group: [447]
[2022-11-04T21:27:38.048+0000] {process_utils.py:84} INFO - Sending the signal Signals.SIGTERM to group 447
[2022-11-04T21:27:38.069+0000] {process_utils.py:79} INFO - Process psutil.Process(pid=447, status='terminated', exitcode=<Negsignal.SIGTERM: -15>, started='21:13:39') (447) terminated with exit code Negsignal.SIGTERM
[2022-11-04T21:33:27.527+0000] {taskinstance.py:1165} INFO - Dependencies all met for <TaskInstance: orquestation.task2 scheduled__2022-05-25T00:00:00+00:00 [queued]>
[2022-11-04T21:33:27.549+0000] {taskinstance.py:1165} INFO - Dependencies all met for <TaskInstance: orquestation.task2 scheduled__2022-05-25T00:00:00+00:00 [queued]>
[2022-11-04T21:33:27.550+0000] {taskinstance.py:1362} INFO - 
--------------------------------------------------------------------------------
[2022-11-04T21:33:27.551+0000] {taskinstance.py:1363} INFO - Starting attempt 1 of 1
[2022-11-04T21:33:27.551+0000] {taskinstance.py:1364} INFO - 
--------------------------------------------------------------------------------
[2022-11-04T21:33:27.576+0000] {taskinstance.py:1383} INFO - Executing <Task(BashOperator): task2> on 2022-05-25 00:00:00+00:00
[2022-11-04T21:33:27.584+0000] {standard_task_runner.py:55} INFO - Started process 1091 to run task
[2022-11-04T21:33:27.594+0000] {standard_task_runner.py:82} INFO - Running: ['***', 'tasks', 'run', 'orquestation', 'task2', 'scheduled__2022-05-25T00:00:00+00:00', '--job-id', '205', '--raw', '--subdir', 'DAGS_FOLDER/5.1-orquestacion.py', '--cfg-path', '/tmp/tmpf3u94bh6']
[2022-11-04T21:33:27.596+0000] {standard_task_runner.py:83} INFO - Job 205: Subtask task2
[2022-11-04T21:33:27.701+0000] {task_command.py:376} INFO - Running <TaskInstance: orquestation.task2 scheduled__2022-05-25T00:00:00+00:00 [running]> on host 643e334f405f
[2022-11-04T21:33:27.814+0000] {taskinstance.py:1592} INFO - Exporting the following env vars:
AIRFLOW_CTX_DAG_OWNER=***
AIRFLOW_CTX_DAG_ID=orquestation
AIRFLOW_CTX_TASK_ID=task2
AIRFLOW_CTX_EXECUTION_DATE=2022-05-25T00:00:00+00:00
AIRFLOW_CTX_TRY_NUMBER=1
AIRFLOW_CTX_DAG_RUN_ID=scheduled__2022-05-25T00:00:00+00:00
[2022-11-04T21:33:27.816+0000] {subprocess.py:63} INFO - Tmp dir root location: 
 /tmp
[2022-11-04T21:33:27.818+0000] {subprocess.py:75} INFO - Running command: ['/bin/bash', '-c', "sleep 2 && echo 'task2'"]
[2022-11-04T21:33:27.838+0000] {subprocess.py:86} INFO - Output:
[2022-11-04T21:33:29.870+0000] {subprocess.py:93} INFO - task2
[2022-11-04T21:33:29.874+0000] {subprocess.py:97} INFO - Command exited with return code 0
[2022-11-04T21:33:30.009+0000] {taskinstance.py:1406} INFO - Marking task as SUCCESS. dag_id=orquestation, task_id=task2, execution_date=20220525T000000, start_date=20221104T213327, end_date=20221104T213330
[2022-11-04T21:33:30.170+0000] {local_task_job.py:164} INFO - Task exited with return code 0
[2022-11-04T21:33:30.562+0000] {local_task_job.py:273} INFO - 0 downstream tasks scheduled from follow-on schedule check
[2022-11-04T21:44:27.882+0000] {taskinstance.py:1165} INFO - Dependencies all met for <TaskInstance: orquestation.task2 scheduled__2022-05-25T00:00:00+00:00 [queued]>
[2022-11-04T21:44:27.899+0000] {taskinstance.py:1165} INFO - Dependencies all met for <TaskInstance: orquestation.task2 scheduled__2022-05-25T00:00:00+00:00 [queued]>
[2022-11-04T21:44:27.900+0000] {taskinstance.py:1362} INFO - 
--------------------------------------------------------------------------------
[2022-11-04T21:44:27.900+0000] {taskinstance.py:1363} INFO - Starting attempt 1 of 1
[2022-11-04T21:44:27.900+0000] {taskinstance.py:1364} INFO - 
--------------------------------------------------------------------------------
[2022-11-04T21:44:27.917+0000] {taskinstance.py:1383} INFO - Executing <Task(BashOperator): task2> on 2022-05-25 00:00:00+00:00
[2022-11-04T21:44:27.924+0000] {standard_task_runner.py:55} INFO - Started process 2182 to run task
[2022-11-04T21:44:27.927+0000] {standard_task_runner.py:82} INFO - Running: ['***', 'tasks', 'run', 'orquestation', 'task2', 'scheduled__2022-05-25T00:00:00+00:00', '--job-id', '352', '--raw', '--subdir', 'DAGS_FOLDER/5.1-orquestacion.py', '--cfg-path', '/tmp/tmpcau856r9']
[2022-11-04T21:44:27.928+0000] {standard_task_runner.py:83} INFO - Job 352: Subtask task2
[2022-11-04T21:44:27.993+0000] {task_command.py:376} INFO - Running <TaskInstance: orquestation.task2 scheduled__2022-05-25T00:00:00+00:00 [running]> on host 643e334f405f
[2022-11-04T21:44:28.069+0000] {taskinstance.py:1592} INFO - Exporting the following env vars:
AIRFLOW_CTX_DAG_OWNER=***
AIRFLOW_CTX_DAG_ID=orquestation
AIRFLOW_CTX_TASK_ID=task2
AIRFLOW_CTX_EXECUTION_DATE=2022-05-25T00:00:00+00:00
AIRFLOW_CTX_TRY_NUMBER=1
AIRFLOW_CTX_DAG_RUN_ID=scheduled__2022-05-25T00:00:00+00:00
[2022-11-04T21:44:28.071+0000] {subprocess.py:63} INFO - Tmp dir root location: 
 /tmp
[2022-11-04T21:44:28.072+0000] {subprocess.py:75} INFO - Running command: ['/bin/bash', '-c', "sleep 2 && echo 'task2'"]
[2022-11-04T21:44:28.085+0000] {subprocess.py:86} INFO - Output:
[2022-11-04T21:44:30.088+0000] {subprocess.py:93} INFO - task2
[2022-11-04T21:44:30.089+0000] {subprocess.py:97} INFO - Command exited with return code 0
[2022-11-04T21:44:30.121+0000] {taskinstance.py:1406} INFO - Marking task as SUCCESS. dag_id=orquestation, task_id=task2, execution_date=20220525T000000, start_date=20221104T214427, end_date=20221104T214430
[2022-11-04T21:44:30.146+0000] {local_task_job.py:164} INFO - Task exited with return code 0
[2022-11-04T21:44:30.183+0000] {local_task_job.py:273} INFO - 2 downstream tasks scheduled from follow-on schedule check
