[2022-11-08T18:24:33.607+0000] {taskinstance.py:1165} INFO - Dependencies all met for <TaskInstance: 6-monitoring_1.task4 scheduled__2022-01-31T00:00:00+00:00 [queued]>
[2022-11-08T18:24:33.623+0000] {taskinstance.py:1165} INFO - Dependencies all met for <TaskInstance: 6-monitoring_1.task4 scheduled__2022-01-31T00:00:00+00:00 [queued]>
[2022-11-08T18:24:33.624+0000] {taskinstance.py:1362} INFO - 
--------------------------------------------------------------------------------
[2022-11-08T18:24:33.625+0000] {taskinstance.py:1363} INFO - Starting attempt 1 of 1
[2022-11-08T18:24:33.626+0000] {taskinstance.py:1364} INFO - 
--------------------------------------------------------------------------------
[2022-11-08T18:24:33.659+0000] {taskinstance.py:1383} INFO - Executing <Task(PythonOperator): task4> on 2022-01-31 00:00:00+00:00
[2022-11-08T18:24:33.668+0000] {standard_task_runner.py:55} INFO - Started process 914 to run task
[2022-11-08T18:24:33.671+0000] {standard_task_runner.py:82} INFO - Running: ['***', 'tasks', 'run', '6-monitoring_1', 'task4', 'scheduled__2022-01-31T00:00:00+00:00', '--job-id', '462', '--raw', '--subdir', 'DAGS_FOLDER/6.1-monitoring.py', '--cfg-path', '/tmp/tmpticayew6']
[2022-11-08T18:24:33.673+0000] {standard_task_runner.py:83} INFO - Job 462: Subtask task4
[2022-11-08T18:24:33.756+0000] {task_command.py:376} INFO - Running <TaskInstance: 6-monitoring_1.task4 scheduled__2022-01-31T00:00:00+00:00 [running]> on host 638485efabe7
[2022-11-08T18:24:33.833+0000] {taskinstance.py:1592} INFO - Exporting the following env vars:
AIRFLOW_CTX_DAG_OWNER=***
AIRFLOW_CTX_DAG_ID=6-monitoring_1
AIRFLOW_CTX_TASK_ID=task4
AIRFLOW_CTX_EXECUTION_DATE=2022-01-31T00:00:00+00:00
AIRFLOW_CTX_TRY_NUMBER=1
AIRFLOW_CTX_DAG_RUN_ID=scheduled__2022-01-31T00:00:00+00:00
[2022-11-08T18:24:33.835+0000] {taskinstance.py:1851} ERROR - Task failed with exception
Traceback (most recent call last):
  File "/home/airflow/.local/lib/python3.7/site-packages/airflow/operators/python.py", line 175, in execute
    return_value = self.execute_callable()
  File "/home/airflow/.local/lib/python3.7/site-packages/airflow/operators/python.py", line 193, in execute_callable
    return self.python_callable(*self.op_args, **self.op_kwargs)
  File "/opt/airflow/dags/6.1-monitoring.py", line 7, in myfunction
    raise Exception
Exception
[2022-11-08T18:24:33.849+0000] {taskinstance.py:1406} INFO - Marking task as FAILED. dag_id=6-monitoring_1, task_id=task4, execution_date=20220131T000000, start_date=20221108T182433, end_date=20221108T182433
[2022-11-08T18:24:33.869+0000] {standard_task_runner.py:105} ERROR - Failed to execute job 462 for task task4 (; 914)
[2022-11-08T18:24:33.967+0000] {local_task_job.py:164} INFO - Task exited with return code 1
[2022-11-08T18:24:34.014+0000] {local_task_job.py:273} INFO - 0 downstream tasks scheduled from follow-on schedule check
