[2022-11-04T19:40:47.864+0000] {taskinstance.py:1165} INFO - Dependencies all met for <TaskInstance: orquestation.TASK1 scheduled__2022-05-13T00:00:00+00:00 [queued]>
[2022-11-04T19:40:47.899+0000] {taskinstance.py:1165} INFO - Dependencies all met for <TaskInstance: orquestation.TASK1 scheduled__2022-05-13T00:00:00+00:00 [queued]>
[2022-11-04T19:40:47.900+0000] {taskinstance.py:1362} INFO - 
--------------------------------------------------------------------------------
[2022-11-04T19:40:47.901+0000] {taskinstance.py:1363} INFO - Starting attempt 1 of 1
[2022-11-04T19:40:47.905+0000] {taskinstance.py:1364} INFO - 
--------------------------------------------------------------------------------
[2022-11-04T19:40:48.271+0000] {taskinstance.py:1383} INFO - Executing <Task(BashOperator): TASK1> on 2022-05-13 00:00:00+00:00
[2022-11-04T19:40:48.278+0000] {standard_task_runner.py:55} INFO - Started process 231 to run task
[2022-11-04T19:40:48.290+0000] {standard_task_runner.py:82} INFO - Running: ['***', 'tasks', 'run', 'orquestation', 'TASK1', 'scheduled__2022-05-13T00:00:00+00:00', '--job-id', '8', '--raw', '--subdir', 'DAGS_FOLDER/5.1-orquestacion.py', '--cfg-path', '/tmp/tmppq3zypqr']
[2022-11-04T19:40:48.291+0000] {standard_task_runner.py:83} INFO - Job 8: Subtask TASK1
[2022-11-04T19:40:49.065+0000] {task_command.py:376} INFO - Running <TaskInstance: orquestation.TASK1 scheduled__2022-05-13T00:00:00+00:00 [running]> on host 208ed96b478a
[2022-11-04T19:43:05.723+0000] {standard_task_runner.py:105} ERROR - Failed to execute job 8 for task TASK1 ((psycopg2.OperationalError) could not translate host name "postgres" to address: Temporary failure in name resolution

(Background on this error at: https://sqlalche.me/e/14/e3q8); 231)
[2022-11-04T19:41:28.420+0000] {base_job.py:232} ERROR - LocalTaskJob heartbeat got an exception
Traceback (most recent call last):
  File "/home/airflow/.local/lib/python3.7/site-packages/sqlalchemy/engine/base.py", line 3243, in _wrap_pool_connect
    return fn()
  File "/home/airflow/.local/lib/python3.7/site-packages/sqlalchemy/pool/base.py", line 310, in connect
    return _ConnectionFairy._checkout(self)
  File "/home/airflow/.local/lib/python3.7/site-packages/sqlalchemy/pool/base.py", line 868, in _checkout
    fairy = _ConnectionRecord.checkout(pool)
  File "/home/airflow/.local/lib/python3.7/site-packages/sqlalchemy/pool/base.py", line 476, in checkout
    rec = pool._do_get()
  File "/home/airflow/.local/lib/python3.7/site-packages/sqlalchemy/pool/impl.py", line 256, in _do_get
    return self._create_connection()
  File "/home/airflow/.local/lib/python3.7/site-packages/sqlalchemy/pool/base.py", line 256, in _create_connection
    return _ConnectionRecord(self)
  File "/home/airflow/.local/lib/python3.7/site-packages/sqlalchemy/pool/base.py", line 371, in __init__
    self.__connect()
  File "/home/airflow/.local/lib/python3.7/site-packages/sqlalchemy/pool/base.py", line 666, in __connect
    pool.logger.debug("Error on connect(): %s", e)
  File "/home/airflow/.local/lib/python3.7/site-packages/sqlalchemy/util/langhelpers.py", line 72, in __exit__
    with_traceback=exc_tb,
  File "/home/airflow/.local/lib/python3.7/site-packages/sqlalchemy/util/compat.py", line 207, in raise_
    raise exception
  File "/home/airflow/.local/lib/python3.7/site-packages/sqlalchemy/pool/base.py", line 661, in __connect
    self.dbapi_connection = connection = pool._invoke_creator(self)
  File "/home/airflow/.local/lib/python3.7/site-packages/sqlalchemy/engine/create.py", line 590, in connect
    return dialect.connect(*cargs, **cparams)
  File "/home/airflow/.local/lib/python3.7/site-packages/sqlalchemy/engine/default.py", line 584, in connect
    return self.dbapi.connect(*cargs, **cparams)
  File "/home/airflow/.local/lib/python3.7/site-packages/psycopg2/__init__.py", line 122, in connect
    conn = _connect(dsn, connection_factory=connection_factory, **kwasync)
psycopg2.OperationalError: could not translate host name "postgres" to address: Temporary failure in name resolution


The above exception was the direct cause of the following exception:

Traceback (most recent call last):
  File "/home/airflow/.local/lib/python3.7/site-packages/airflow/jobs/base_job.py", line 204, in heartbeat
    session.merge(self)
  File "/home/airflow/.local/lib/python3.7/site-packages/sqlalchemy/orm/session.py", line 2961, in merge
    _resolve_conflict_map=_resolve_conflict_map,
  File "/home/airflow/.local/lib/python3.7/site-packages/sqlalchemy/orm/session.py", line 3039, in _merge
    options=options,
  File "/home/airflow/.local/lib/python3.7/site-packages/sqlalchemy/orm/session.py", line 2775, in get
    identity_token=identity_token,
  File "/home/airflow/.local/lib/python3.7/site-packages/sqlalchemy/orm/session.py", line 2878, in _get_impl
    load_options=load_options,
  File "/home/airflow/.local/lib/python3.7/site-packages/sqlalchemy/orm/loading.py", line 534, in load_on_pk_identity
    bind_arguments=bind_arguments,
  File "/home/airflow/.local/lib/python3.7/site-packages/sqlalchemy/orm/session.py", line 1688, in execute
    conn = self._connection_for_bind(bind)
  File "/home/airflow/.local/lib/python3.7/site-packages/sqlalchemy/orm/session.py", line 1530, in _connection_for_bind
    engine, execution_options
  File "/home/airflow/.local/lib/python3.7/site-packages/sqlalchemy/orm/session.py", line 747, in _connection_for_bind
    conn = bind.connect()
  File "/home/airflow/.local/lib/python3.7/site-packages/sqlalchemy/engine/base.py", line 3197, in connect
    return self._connection_cls(self, close_with_result=close_with_result)
  File "/home/airflow/.local/lib/python3.7/site-packages/sqlalchemy/engine/base.py", line 96, in __init__
    else engine.raw_connection()
  File "/home/airflow/.local/lib/python3.7/site-packages/sqlalchemy/engine/base.py", line 3276, in raw_connection
    return self._wrap_pool_connect(self.pool.connect, _connection)
  File "/home/airflow/.local/lib/python3.7/site-packages/sqlalchemy/engine/base.py", line 3247, in _wrap_pool_connect
    e, dialect, self
  File "/home/airflow/.local/lib/python3.7/site-packages/sqlalchemy/engine/base.py", line 2101, in _handle_dbapi_exception_noconnection
    sqlalchemy_exception, with_traceback=exc_info[2], from_=e
  File "/home/airflow/.local/lib/python3.7/site-packages/sqlalchemy/util/compat.py", line 207, in raise_
    raise exception
  File "/home/airflow/.local/lib/python3.7/site-packages/sqlalchemy/engine/base.py", line 3243, in _wrap_pool_connect
    return fn()
  File "/home/airflow/.local/lib/python3.7/site-packages/sqlalchemy/pool/base.py", line 310, in connect
    return _ConnectionFairy._checkout(self)
  File "/home/airflow/.local/lib/python3.7/site-packages/sqlalchemy/pool/base.py", line 868, in _checkout
    fairy = _ConnectionRecord.checkout(pool)
  File "/home/airflow/.local/lib/python3.7/site-packages/sqlalchemy/pool/base.py", line 476, in checkout
    rec = pool._do_get()
  File "/home/airflow/.local/lib/python3.7/site-packages/sqlalchemy/pool/impl.py", line 256, in _do_get
    return self._create_connection()
  File "/home/airflow/.local/lib/python3.7/site-packages/sqlalchemy/pool/base.py", line 256, in _create_connection
    return _ConnectionRecord(self)
  File "/home/airflow/.local/lib/python3.7/site-packages/sqlalchemy/pool/base.py", line 371, in __init__
    self.__connect()
  File "/home/airflow/.local/lib/python3.7/site-packages/sqlalchemy/pool/base.py", line 666, in __connect
    pool.logger.debug("Error on connect(): %s", e)
  File "/home/airflow/.local/lib/python3.7/site-packages/sqlalchemy/util/langhelpers.py", line 72, in __exit__
    with_traceback=exc_tb,
  File "/home/airflow/.local/lib/python3.7/site-packages/sqlalchemy/util/compat.py", line 207, in raise_
    raise exception
  File "/home/airflow/.local/lib/python3.7/site-packages/sqlalchemy/pool/base.py", line 661, in __connect
    self.dbapi_connection = connection = pool._invoke_creator(self)
  File "/home/airflow/.local/lib/python3.7/site-packages/sqlalchemy/engine/create.py", line 590, in connect
    return dialect.connect(*cargs, **cparams)
  File "/home/airflow/.local/lib/python3.7/site-packages/sqlalchemy/engine/default.py", line 584, in connect
    return self.dbapi.connect(*cargs, **cparams)
  File "/home/airflow/.local/lib/python3.7/site-packages/psycopg2/__init__.py", line 122, in connect
    conn = _connect(dsn, connection_factory=connection_factory, **kwasync)
sqlalchemy.exc.OperationalError: (psycopg2.OperationalError) could not translate host name "postgres" to address: Temporary failure in name resolution

(Background on this error at: https://sqlalche.me/e/14/e3q8)
[2022-11-04T19:43:48.190+0000] {local_task_job.py:164} INFO - Task exited with return code 1
[2022-11-04T19:44:02.283+0000] {local_task_job.py:281} INFO - Skipping mini scheduling run due to exception: None
Traceback (most recent call last):
  File "/home/airflow/.local/lib/python3.7/site-packages/sqlalchemy/engine/base.py", line 3243, in _wrap_pool_connect
    return fn()
  File "/home/airflow/.local/lib/python3.7/site-packages/sqlalchemy/pool/base.py", line 310, in connect
    return _ConnectionFairy._checkout(self)
  File "/home/airflow/.local/lib/python3.7/site-packages/sqlalchemy/pool/base.py", line 868, in _checkout
    fairy = _ConnectionRecord.checkout(pool)
  File "/home/airflow/.local/lib/python3.7/site-packages/sqlalchemy/pool/base.py", line 476, in checkout
    rec = pool._do_get()
  File "/home/airflow/.local/lib/python3.7/site-packages/sqlalchemy/pool/impl.py", line 256, in _do_get
    return self._create_connection()
  File "/home/airflow/.local/lib/python3.7/site-packages/sqlalchemy/pool/base.py", line 256, in _create_connection
    return _ConnectionRecord(self)
  File "/home/airflow/.local/lib/python3.7/site-packages/sqlalchemy/pool/base.py", line 371, in __init__
    self.__connect()
  File "/home/airflow/.local/lib/python3.7/site-packages/sqlalchemy/pool/base.py", line 666, in __connect
    pool.logger.debug("Error on connect(): %s", e)
  File "/home/airflow/.local/lib/python3.7/site-packages/sqlalchemy/util/langhelpers.py", line 72, in __exit__
    with_traceback=exc_tb,
  File "/home/airflow/.local/lib/python3.7/site-packages/sqlalchemy/util/compat.py", line 207, in raise_
    raise exception
  File "/home/airflow/.local/lib/python3.7/site-packages/sqlalchemy/pool/base.py", line 661, in __connect
    self.dbapi_connection = connection = pool._invoke_creator(self)
  File "/home/airflow/.local/lib/python3.7/site-packages/sqlalchemy/engine/create.py", line 590, in connect
    return dialect.connect(*cargs, **cparams)
  File "/home/airflow/.local/lib/python3.7/site-packages/sqlalchemy/engine/default.py", line 584, in connect
    return self.dbapi.connect(*cargs, **cparams)
  File "/home/airflow/.local/lib/python3.7/site-packages/psycopg2/__init__.py", line 122, in connect
    conn = _connect(dsn, connection_factory=connection_factory, **kwasync)
psycopg2.OperationalError: could not translate host name "postgres" to address: Temporary failure in name resolution


The above exception was the direct cause of the following exception:

Traceback (most recent call last):
  File "/home/airflow/.local/lib/python3.7/site-packages/airflow/jobs/local_task_job.py", line 243, in _run_mini_scheduler_on_child_tasks
    session=session,
  File "/home/airflow/.local/lib/python3.7/site-packages/sqlalchemy/orm/query.py", line 2856, in one
    return self._iter().one()
  File "/home/airflow/.local/lib/python3.7/site-packages/sqlalchemy/orm/query.py", line 2897, in _iter
    execution_options={"_sa_orm_load_options": self.load_options},
  File "/home/airflow/.local/lib/python3.7/site-packages/sqlalchemy/orm/session.py", line 1688, in execute
    conn = self._connection_for_bind(bind)
  File "/home/airflow/.local/lib/python3.7/site-packages/sqlalchemy/orm/session.py", line 1530, in _connection_for_bind
    engine, execution_options
  File "/home/airflow/.local/lib/python3.7/site-packages/sqlalchemy/orm/session.py", line 747, in _connection_for_bind
    conn = bind.connect()
  File "/home/airflow/.local/lib/python3.7/site-packages/sqlalchemy/engine/base.py", line 3197, in connect
    return self._connection_cls(self, close_with_result=close_with_result)
  File "/home/airflow/.local/lib/python3.7/site-packages/sqlalchemy/engine/base.py", line 96, in __init__
    else engine.raw_connection()
  File "/home/airflow/.local/lib/python3.7/site-packages/sqlalchemy/engine/base.py", line 3276, in raw_connection
    return self._wrap_pool_connect(self.pool.connect, _connection)
  File "/home/airflow/.local/lib/python3.7/site-packages/sqlalchemy/engine/base.py", line 3247, in _wrap_pool_connect
    e, dialect, self
  File "/home/airflow/.local/lib/python3.7/site-packages/sqlalchemy/engine/base.py", line 2101, in _handle_dbapi_exception_noconnection
    sqlalchemy_exception, with_traceback=exc_info[2], from_=e
  File "/home/airflow/.local/lib/python3.7/site-packages/sqlalchemy/util/compat.py", line 207, in raise_
    raise exception
  File "/home/airflow/.local/lib/python3.7/site-packages/sqlalchemy/engine/base.py", line 3243, in _wrap_pool_connect
    return fn()
  File "/home/airflow/.local/lib/python3.7/site-packages/sqlalchemy/pool/base.py", line 310, in connect
    return _ConnectionFairy._checkout(self)
  File "/home/airflow/.local/lib/python3.7/site-packages/sqlalchemy/pool/base.py", line 868, in _checkout
    fairy = _ConnectionRecord.checkout(pool)
  File "/home/airflow/.local/lib/python3.7/site-packages/sqlalchemy/pool/base.py", line 476, in checkout
    rec = pool._do_get()
  File "/home/airflow/.local/lib/python3.7/site-packages/sqlalchemy/pool/impl.py", line 256, in _do_get
    return self._create_connection()
  File "/home/airflow/.local/lib/python3.7/site-packages/sqlalchemy/pool/base.py", line 256, in _create_connection
    return _ConnectionRecord(self)
  File "/home/airflow/.local/lib/python3.7/site-packages/sqlalchemy/pool/base.py", line 371, in __init__
    self.__connect()
  File "/home/airflow/.local/lib/python3.7/site-packages/sqlalchemy/pool/base.py", line 666, in __connect
    pool.logger.debug("Error on connect(): %s", e)
  File "/home/airflow/.local/lib/python3.7/site-packages/sqlalchemy/util/langhelpers.py", line 72, in __exit__
    with_traceback=exc_tb,
  File "/home/airflow/.local/lib/python3.7/site-packages/sqlalchemy/util/compat.py", line 207, in raise_
    raise exception
  File "/home/airflow/.local/lib/python3.7/site-packages/sqlalchemy/pool/base.py", line 661, in __connect
    self.dbapi_connection = connection = pool._invoke_creator(self)
  File "/home/airflow/.local/lib/python3.7/site-packages/sqlalchemy/engine/create.py", line 590, in connect
    return dialect.connect(*cargs, **cparams)
  File "/home/airflow/.local/lib/python3.7/site-packages/sqlalchemy/engine/default.py", line 584, in connect
    return self.dbapi.connect(*cargs, **cparams)
  File "/home/airflow/.local/lib/python3.7/site-packages/psycopg2/__init__.py", line 122, in connect
    conn = _connect(dsn, connection_factory=connection_factory, **kwasync)
sqlalchemy.exc.OperationalError: (psycopg2.OperationalError) could not translate host name "postgres" to address: Temporary failure in name resolution

(Background on this error at: https://sqlalche.me/e/14/e3q8)
[2022-11-04T21:32:31.486+0000] {taskinstance.py:1165} INFO - Dependencies all met for <TaskInstance: orquestation.task1 scheduled__2022-05-13T00:00:00+00:00 [queued]>
[2022-11-04T21:32:31.518+0000] {taskinstance.py:1165} INFO - Dependencies all met for <TaskInstance: orquestation.task1 scheduled__2022-05-13T00:00:00+00:00 [queued]>
[2022-11-04T21:32:31.519+0000] {taskinstance.py:1362} INFO - 
--------------------------------------------------------------------------------
[2022-11-04T21:32:31.520+0000] {taskinstance.py:1363} INFO - Starting attempt 1 of 1
[2022-11-04T21:32:31.521+0000] {taskinstance.py:1364} INFO - 
--------------------------------------------------------------------------------
[2022-11-04T21:32:31.563+0000] {taskinstance.py:1383} INFO - Executing <Task(BashOperator): task1> on 2022-05-13 00:00:00+00:00
[2022-11-04T21:32:31.579+0000] {standard_task_runner.py:55} INFO - Started process 847 to run task
[2022-11-04T21:32:31.589+0000] {standard_task_runner.py:82} INFO - Running: ['***', 'tasks', 'run', 'orquestation', 'task1', 'scheduled__2022-05-13T00:00:00+00:00', '--job-id', '155', '--raw', '--subdir', 'DAGS_FOLDER/5.1-orquestacion.py', '--cfg-path', '/tmp/tmpcdtbm3od']
[2022-11-04T21:32:31.591+0000] {standard_task_runner.py:83} INFO - Job 155: Subtask task1
[2022-11-04T21:32:31.765+0000] {task_command.py:376} INFO - Running <TaskInstance: orquestation.task1 scheduled__2022-05-13T00:00:00+00:00 [running]> on host 643e334f405f
[2022-11-04T21:32:31.962+0000] {taskinstance.py:1592} INFO - Exporting the following env vars:
AIRFLOW_CTX_DAG_OWNER=***
AIRFLOW_CTX_DAG_ID=orquestation
AIRFLOW_CTX_TASK_ID=task1
AIRFLOW_CTX_EXECUTION_DATE=2022-05-13T00:00:00+00:00
AIRFLOW_CTX_TRY_NUMBER=1
AIRFLOW_CTX_DAG_RUN_ID=scheduled__2022-05-13T00:00:00+00:00
[2022-11-04T21:32:32.006+0000] {subprocess.py:63} INFO - Tmp dir root location: 
 /tmp
[2022-11-04T21:32:32.011+0000] {subprocess.py:75} INFO - Running command: ['/bin/bash', '-c', "sleep 2 && echo 'task1'"]
[2022-11-04T21:32:32.039+0000] {subprocess.py:86} INFO - Output:
[2022-11-04T21:32:34.675+0000] {subprocess.py:93} INFO - task1
[2022-11-04T21:32:34.678+0000] {subprocess.py:97} INFO - Command exited with return code 0
[2022-11-04T21:32:34.889+0000] {taskinstance.py:1406} INFO - Marking task as SUCCESS. dag_id=orquestation, task_id=task1, execution_date=20220513T000000, start_date=20221104T213231, end_date=20221104T213234
[2022-11-04T21:32:34.992+0000] {local_task_job.py:164} INFO - Task exited with return code 0
[2022-11-04T21:32:35.237+0000] {local_task_job.py:273} INFO - 1 downstream tasks scheduled from follow-on schedule check
[2022-11-04T21:42:14.178+0000] {taskinstance.py:1165} INFO - Dependencies all met for <TaskInstance: orquestation.task1 scheduled__2022-05-13T00:00:00+00:00 [queued]>
[2022-11-04T21:42:14.193+0000] {taskinstance.py:1165} INFO - Dependencies all met for <TaskInstance: orquestation.task1 scheduled__2022-05-13T00:00:00+00:00 [queued]>
[2022-11-04T21:42:14.193+0000] {taskinstance.py:1362} INFO - 
--------------------------------------------------------------------------------
[2022-11-04T21:42:14.194+0000] {taskinstance.py:1363} INFO - Starting attempt 1 of 1
[2022-11-04T21:42:14.194+0000] {taskinstance.py:1364} INFO - 
--------------------------------------------------------------------------------
[2022-11-04T21:42:14.209+0000] {taskinstance.py:1383} INFO - Executing <Task(BashOperator): task1> on 2022-05-13 00:00:00+00:00
[2022-11-04T21:42:14.216+0000] {standard_task_runner.py:55} INFO - Started process 1878 to run task
[2022-11-04T21:42:14.219+0000] {standard_task_runner.py:82} INFO - Running: ['***', 'tasks', 'run', 'orquestation', 'task1', 'scheduled__2022-05-13T00:00:00+00:00', '--job-id', '303', '--raw', '--subdir', 'DAGS_FOLDER/5.1-orquestacion.py', '--cfg-path', '/tmp/tmpr0rg26qj']
[2022-11-04T21:42:14.220+0000] {standard_task_runner.py:83} INFO - Job 303: Subtask task1
[2022-11-04T21:42:14.282+0000] {task_command.py:376} INFO - Running <TaskInstance: orquestation.task1 scheduled__2022-05-13T00:00:00+00:00 [running]> on host 643e334f405f
[2022-11-04T21:42:14.352+0000] {taskinstance.py:1592} INFO - Exporting the following env vars:
AIRFLOW_CTX_DAG_OWNER=***
AIRFLOW_CTX_DAG_ID=orquestation
AIRFLOW_CTX_TASK_ID=task1
AIRFLOW_CTX_EXECUTION_DATE=2022-05-13T00:00:00+00:00
AIRFLOW_CTX_TRY_NUMBER=1
AIRFLOW_CTX_DAG_RUN_ID=scheduled__2022-05-13T00:00:00+00:00
[2022-11-04T21:42:14.354+0000] {subprocess.py:63} INFO - Tmp dir root location: 
 /tmp
[2022-11-04T21:42:14.355+0000] {subprocess.py:75} INFO - Running command: ['/bin/bash', '-c', "sleep 2 && echo 'task1'"]
[2022-11-04T21:42:14.368+0000] {subprocess.py:86} INFO - Output:
[2022-11-04T21:42:16.372+0000] {subprocess.py:93} INFO - task1
[2022-11-04T21:42:16.373+0000] {subprocess.py:97} INFO - Command exited with return code 0
[2022-11-04T21:42:16.399+0000] {taskinstance.py:1406} INFO - Marking task as SUCCESS. dag_id=orquestation, task_id=task1, execution_date=20220513T000000, start_date=20221104T214214, end_date=20221104T214216
[2022-11-04T21:42:16.439+0000] {local_task_job.py:164} INFO - Task exited with return code 0
[2022-11-04T21:42:16.482+0000] {local_task_job.py:273} INFO - 1 downstream tasks scheduled from follow-on schedule check
