[2022-11-08T18:49:56.527+0000] {taskinstance.py:1165} INFO - Dependencies all met for <TaskInstance: 6-monitoring_1.task4 scheduled__2022-01-08T00:00:00+00:00 [queued]>
[2022-11-08T18:49:56.541+0000] {taskinstance.py:1165} INFO - Dependencies all met for <TaskInstance: 6-monitoring_1.task4 scheduled__2022-01-08T00:00:00+00:00 [queued]>
[2022-11-08T18:49:56.542+0000] {taskinstance.py:1362} INFO - 
--------------------------------------------------------------------------------
[2022-11-08T18:49:56.543+0000] {taskinstance.py:1363} INFO - Starting attempt 1 of 1
[2022-11-08T18:49:56.544+0000] {taskinstance.py:1364} INFO - 
--------------------------------------------------------------------------------
[2022-11-08T18:49:56.562+0000] {taskinstance.py:1383} INFO - Executing <Task(PythonOperator): task4> on 2022-01-08 00:00:00+00:00
[2022-11-08T18:49:56.569+0000] {standard_task_runner.py:55} INFO - Started process 1143 to run task
[2022-11-08T18:49:56.572+0000] {standard_task_runner.py:82} INFO - Running: ['***', 'tasks', 'run', '6-monitoring_1', 'task4', 'scheduled__2022-01-08T00:00:00+00:00', '--job-id', '466', '--raw', '--subdir', 'DAGS_FOLDER/6.1-monitoring.py', '--cfg-path', '/tmp/tmpkkyf7alg']
[2022-11-08T18:49:56.573+0000] {standard_task_runner.py:83} INFO - Job 466: Subtask task4
[2022-11-08T18:49:56.639+0000] {task_command.py:376} INFO - Running <TaskInstance: 6-monitoring_1.task4 scheduled__2022-01-08T00:00:00+00:00 [running]> on host 638485efabe7
[2022-11-08T18:49:56.715+0000] {taskinstance.py:1592} INFO - Exporting the following env vars:
AIRFLOW_CTX_DAG_OWNER=***
AIRFLOW_CTX_DAG_ID=6-monitoring_1
AIRFLOW_CTX_TASK_ID=task4
AIRFLOW_CTX_EXECUTION_DATE=2022-01-08T00:00:00+00:00
AIRFLOW_CTX_TRY_NUMBER=1
AIRFLOW_CTX_DAG_RUN_ID=scheduled__2022-01-08T00:00:00+00:00
[2022-11-08T18:49:56.717+0000] {taskinstance.py:1851} ERROR - Task failed with exception
Traceback (most recent call last):
  File "/home/airflow/.local/lib/python3.7/site-packages/airflow/operators/python.py", line 175, in execute
    return_value = self.execute_callable()
  File "/home/airflow/.local/lib/python3.7/site-packages/airflow/operators/python.py", line 193, in execute_callable
    return self.python_callable(*self.op_args, **self.op_kwargs)
  File "/opt/airflow/dags/6.1-monitoring.py", line 7, in myfunction
    raise Exception
Exception
[2022-11-08T18:49:56.741+0000] {taskinstance.py:1406} INFO - Marking task as FAILED. dag_id=6-monitoring_1, task_id=task4, execution_date=20220108T000000, start_date=20221108T184956, end_date=20221108T184956
[2022-11-08T18:49:56.759+0000] {standard_task_runner.py:105} ERROR - Failed to execute job 466 for task task4 (; 1143)
[2022-11-08T18:49:56.774+0000] {local_task_job.py:164} INFO - Task exited with return code 1
[2022-11-08T18:49:56.807+0000] {local_task_job.py:273} INFO - 0 downstream tasks scheduled from follow-on schedule check
